<?xml version="1.0" ?>
<!-- =================================================================================== -->
<!-- |    This document was autogenerated by xacro from robotiq-3f-gripper_articulated.xacro      | -->
<!-- |    EDITING THIS FILE BY HAND IS NOT RECOMMENDED                                 | -->
<!-- =================================================================================== -->

<!--
  Link masses reported by Robotiq:
    palm: 1725.68g
    link_0+link_1: 126.22g
    link_2: 60.1g
    link_3: 24g

  assuming link_1 and link_2 have the same density, using the volumes of
  the visual meshes computed in MeshLab
  (link_1: 6.8207e-5 m^3, link_2: 3.9083e-5),
  density = m/V = 0.0601/3.9083e-5 = 1537.8 kg/m^3.
  Therefore, the mass of link_1 is approximately
  m = dV = 1537.8*6.8207e-5 = 0.10489 kg and the mass of link_0 is
  0.12622-0.10489 = 0.02133 kg
-->

<!--
  Inertial properties of links estimated using visual meshes and Gazebo's
  [inertial estimation tutorial](http://gazebosim.org/tutorials?tut=inertia).
  Each visual mesh was loaded in MeshLab, then scaled up by a factor of 10
  in each dimension as instructed by the tutorial to increase precision.
  After computing geometric measures, the resulting inertia values are divided
  by 10^5.
  MeshLab uses the mesh's computed volume as the mass because density=1. Each
  inertia value should be multiplied by the corresponding link's actual mass
  and divided by its volume (the reported scaled-up volume divided by 10^3).
-->

<!-- 
robotiq-3f-gripper_articulated - articulated version of the robotiq robotiq-3f-gripper,
3 fingered gripper.                                                
-->
<robot name="robotiq-3f-gripper_articulated" xmlns:xacro="http://ros.org/wiki/xacro">
  <link name="finger_1_link_0">
    <visual>
      <origin rpy="0 0 0" xyz="0.020 0 0"/>
      <geometry>
        <mesh filename="../meshes/visual/link_0.obj"/>
      </geometry>
      <material name="green">
        <color rgba="0 1 0 1"/>
      </material>
    </visual>
    <inertial>
      <origin rpy="0 0 0" xyz="0 0 0"/>
      <mass value="0.02133"/>
      <inertia ixx="4.598e-06" ixy="2.211e-07" ixz="0.0" iyy="4.441e-06" iyz="0.0" izz="5.906e-06"/>
    </inertial>
  </link>
  <link name="finger_1_link_1">
    <visual>
      <origin rpy="0 0 -0.52" xyz="0.050 -.028 0"/>
      <geometry>
        <mesh filename="../meshes/visual/link_1.obj"/>
      </geometry>
      <material name="green"/>
    </visual>
    <collision>
      <origin rpy="0 0 -0.61" xyz="0.028 -0.016 0.0"/>
      <geometry>
        <box size="0.048 0.018 0.0308"/>
      </geometry>
      <material name="red">
        <color rgba="1 0 0 1"/>
      </material>
      <surface>
        <friction>
          <ode>
            <mu>1.5</mu>
            <mu2>1.0</mu2>
          </ode>
        </friction>
      </surface>
    </collision>
    <inertial>
      <origin rpy="0 0 0" xyz="0 0 0"/>
      <mass value="0.10489"/>
      <inertia ixx="1.655e-05" ixy="-5.844e-07" ixz="0.0" iyy="7.334e-05" iyz="0.0" izz="8.054e-05"/>
    </inertial>
  </link>
  <link name="finger_1_link_2">
    <!--
			NOTE: This link has an offset in the z-direction based on the models that were
			used to generate grap-it poses.  With the offset below the model appears visually
			correct, but it is suspect.
			-->
    <visual>
      <origin rpy="0 0 0" xyz="0.039 0 0.0075"/>
      <geometry>
        <mesh filename="../meshes/visual/link_2.obj"/>
      </geometry>
      <material name="green"/>
    </visual>
    <collision>
      <origin rpy="0 0 0.0" xyz="0.023 0.002 0.0"/>
      <geometry>
        <box size="0.0285 0.01 0.0308"/>
      </geometry>
      <material name="red">
        <color rgba="1 0 0 1"/>
      </material>
      <surface>
        <friction>
          <ode>
            <mu>1.5</mu>
            <mu2>1.0</mu2>
          </ode>
        </friction>
      </surface>
    </collision>
    <inertial>
      <origin rpy="0 0 0" xyz="0 0 0"/>
      <mass value="0.0601"/>
      <inertia ixx="7.304e-06" ixy="-2.645e-06" ixz="3.537e-07" iyy="1.918e-05" iyz="6.920e-07" izz="2.214e-05"/>
    </inertial>
  </link>
  <link name="finger_1_link_3">
    <visual>
      <origin rpy="0 0 0.52" xyz="0 0 0"/>
      <geometry>
        <mesh filename="../meshes/visual/link_3.obj"/>
      </geometry>
      <material name="green"/>
    </visual>
    <collision>
      <origin rpy="0 0 0.58" xyz="0.015 0.0135 0.0"/>
      <geometry>
        <box size="0.03 0.007 0.0308"/>
      </geometry>
      <material name="red">
        <color rgba="1 0 0 1"/>
      </material>
      <surface>
        <friction>
          <ode>
            <mu>1.5</mu>
            <mu2>1.0</mu2>
          </ode>
        </friction>
      </surface>
    </collision>
    <inertial>
      <origin rpy="0 0 0" xyz="0 0 0"/>
      <mass value="0.024"/>
      <inertia ixx="2.021e-06" ixy="-7.733e-07" ixz="-1.031e-08" iyy="4.908e-06" iyz="0.0" izz="4.578e-06"/>
    </inertial>
  </link>
  <joint name="finger_1_joint_1" type="revolute">
    <parent link="finger_1_link_0"/>
    <child link="finger_1_link_1"/>
    <axis xyz="0 0 1"/>
    <origin rpy="0 0 0" xyz="0.020 0 0"/>
    <limit effort="100" lower="0" upper="1.2217304764" velocity="100"/>
  </joint>
  <transmission name="finger_1_transmission_1">
    <type>transmission_interface/SimpleTransmission</type>
    <joint name="finger_1_joint_1"/>
    <actuator name="finger_1_actuator_1"/>
  </transmission>
  <joint name="finger_1_joint_2" type="fixed">
    <parent link="finger_1_link_1"/>
    <child link="finger_1_link_2"/>
    <axis xyz="0 0 1"/>
    <origin rpy="0 0 -0.52" xyz="0.050 -.028 0"/>
    <!--<limit effort="100" lower="0" upper="1.57079632679" velocity="100"/>-->
  </joint>
  <!--<transmission name="finger_1_transmission_2">
    <type>transmission_interface/SimpleTransmission</type>
    <joint name="finger_1_joint_2"/>
    <actuator name="finger_1_actuator_2"/>
  </transmission>-->
  <joint name="finger_1_joint_3" type="revolute">
    <parent link="finger_1_link_2"/>
    <child link="finger_1_link_3"/>
    <axis xyz="0 0 1"/>
    <origin rpy="0 0 0" xyz="0.039 0 0"/>
    <!-- upper limit -0.0523598775598 -->
    <limit effort="100" lower="-1.2217304764" upper="1.0" velocity="100"/>
  </joint>
  <transmission name="finger_1_transmission_3">
    <type>transmission_interface/SimpleTransmission</type>
    <joint name="finger_1_joint_3"/>
    <actuator name="finger_1_actuator_3"/>
  </transmission>
  <link name="finger_2_link_0">
    <visual>
      <origin rpy="0 0 0" xyz="0.020 0 0"/>
      <geometry>
        <mesh filename="../meshes/visual/link_0.obj"/>
      </geometry>
      <material name="green">
        <color rgba="0 1 0 1"/>
      </material>
    </visual>
    <inertial>
      <origin rpy="0 0 0" xyz="0 0 0"/>
      <mass value="0.02133"/>
      <inertia ixx="4.598e-06" ixy="2.211e-07" ixz="0.0" iyy="4.441e-06" iyz="0.0" izz="5.906e-06"/>
    </inertial>
  </link>
  <link name="finger_2_link_1">
    <visual>
      <origin rpy="0 0 -0.52" xyz="0.050 -.028 0"/>
      <geometry>
        <mesh filename="../meshes/visual/link_1.obj"/>
      </geometry>
      <material name="green"/>
    </visual>
    <collision>
      <origin rpy="0 0 -0.61" xyz="0.028 -0.016 0.0"/>
      <geometry>
        <box size="0.048 0.018 0.0308"/>
      </geometry>
      <material name="red">
        <color rgba="1 0 0 1"/>
      </material>
      <surface>
        <friction>
          <ode>
            <mu>1.5</mu>
            <mu2>1.0</mu2>
          </ode>
        </friction>
      </surface>
    </collision>
    <inertial>
      <origin rpy="0 0 0" xyz="0 0 0"/>
      <mass value="0.10489"/>
      <inertia ixx="1.655e-05" ixy="-5.844e-07" ixz="0.0" iyy="7.334e-05" iyz="0.0" izz="8.054e-05"/>
    </inertial>
  </link>
  <link name="finger_2_link_2">
    <!--
			NOTE: This link has an offset in the z-direction based on the models that were
			used to generate grap-it poses.  With the offset below the model appears visually
			correct, but it is suspect.
			-->
    <visual>
      <origin rpy="0 0 0" xyz="0.039 0 0.0075"/>
      <geometry>
        <mesh filename="../meshes/visual/link_2.obj"/>
      </geometry>
      <material name="green"/>
    </visual>
    <collision>
      <origin rpy="0 0 0.0" xyz="0.023 0.002 0.0"/>
      <geometry>
        <box size="0.0285 0.01 0.0308"/>
      </geometry>
      <material name="red">
        <color rgba="1 0 0 1"/>
      </material>
      <surface>
        <friction>
          <ode>
            <mu>1.5</mu>
            <mu2>1.0</mu2>
          </ode>
        </friction>
      </surface>
    </collision>
    <inertial>
      <origin rpy="0 0 0" xyz="0 0 0"/>
      <mass value="0.0601"/>
      <inertia ixx="7.304e-06" ixy="-2.645e-06" ixz="3.537e-07" iyy="1.918e-05" iyz="6.920e-07" izz="2.214e-05"/>
    </inertial>
  </link>
  <link name="finger_2_link_3">
    <visual>
      <origin rpy="0 0 0.52" xyz="0 0 0"/>
      <geometry>
        <mesh filename="../meshes/visual/link_3.obj"/>
      </geometry>
      <material name="green"/>
    </visual>
    <collision>
      <origin rpy="0 0 0.58" xyz="0.015 0.0135 0.0"/>
      <geometry>
        <box size="0.03 0.007 0.0308"/>
      </geometry>
      <material name="red">
        <color rgba="1 0 0 1"/>
      </material>
      <surface>
        <friction>
          <ode>
            <mu>1.5</mu>
            <mu2>1.0</mu2>
          </ode>
        </friction>
      </surface>
    </collision>
    <inertial>
      <origin rpy="0 0 0" xyz="0 0 0"/>
      <mass value="0.024"/>
      <inertia ixx="2.021e-06" ixy="-7.733e-07" ixz="-1.031e-08" iyy="4.908e-06" iyz="0.0" izz="4.578e-06"/>
    </inertial>
  </link>
  <joint name="finger_2_joint_1" type="revolute">
    <parent link="finger_2_link_0"/>
    <child link="finger_2_link_1"/>
    <axis xyz="0 0 1"/>
    <origin rpy="0 0 0" xyz="0.020 0 0"/>
    <limit effort="100" lower="0" upper="1.2217304764" velocity="100"/>
  </joint>
  <transmission name="finger_2_transmission_1">
    <type>transmission_interface/SimpleTransmission</type>
    <joint name="finger_2_joint_1"/>
    <actuator name="finger_2_actuator_1"/>
  </transmission>
  <joint name="finger_2_joint_2" type="fixed">
    <parent link="finger_2_link_1"/>
    <child link="finger_2_link_2"/>
    <axis xyz="0 0 1"/>
    <origin rpy="0 0 -0.52" xyz="0.050 -.028 0"/>
    <!--<limit effort="100" lower="0" upper="1.57079632679" velocity="100"/>-->
  </joint>
  <!--<transmission name="finger_2_transmission_2">
    <type>transmission_interface/SimpleTransmission</type>
    <joint name="finger_2_joint_2"/>
    <actuator name="finger_2_actuator_2"/>
  </transmission>-->
  <joint name="finger_2_joint_3" type="revolute">
    <parent link="finger_2_link_2"/>
    <child link="finger_2_link_3"/>
    <axis xyz="0 0 1"/>
    <origin rpy="0 0 0" xyz="0.039 0 0"/>
    <!-- upper limit -0.0523598775598 -->
    <limit effort="100" lower="-1.2217304764" upper="1.0" velocity="100"/>
  </joint>
  <transmission name="finger_2_transmission_3">
    <type>transmission_interface/SimpleTransmission</type>
    <joint name="finger_2_joint_3"/>
    <actuator name="finger_2_actuator_3"/>
  </transmission>
  <link name="finger_middle_link_0">
    <visual>
      <origin rpy="0 0 0" xyz="0.020 0 0"/>
      <geometry>
        <mesh filename="../meshes/visual/link_0.obj"/>
      </geometry>
      <material name="green">
        <color rgba="0 1 0 1"/>
      </material>
    </visual>
    <inertial>
      <origin rpy="0 0 0" xyz="0 0 0"/>
      <mass value="0.02133"/>
      <inertia ixx="4.598e-06" ixy="2.211e-07" ixz="0.0" iyy="4.441e-06" iyz="0.0" izz="5.906e-06"/>
    </inertial>
  </link>
  <link name="finger_middle_link_1">
    <visual>
      <origin rpy="0 0 -0.52" xyz="0.050 -.028 0"/>
      <geometry>
        <mesh filename="../meshes/visual/link_1.obj"/>
      </geometry>
      <material name="green"/>
    </visual>
    <collision>
      <origin rpy="0 0 -0.61" xyz="0.028 -0.016 0.0"/>
      <geometry>
        <box size="0.048 0.018 0.0308"/>
      </geometry>
      <material name="red">
        <color rgba="1 0 0 1"/>
      </material>
      <surface>
        <friction>
          <ode>
            <mu>1.5</mu>
            <mu2>1.0</mu2>
          </ode>
        </friction>
      </surface>
    </collision>
    <inertial>
      <origin rpy="0 0 0" xyz="0 0 0"/>
      <mass value="0.10489"/>
      <inertia ixx="1.655e-05" ixy="-5.844e-07" ixz="0.0" iyy="7.334e-05" iyz="0.0" izz="8.054e-05"/>
    </inertial>
  </link>
  <link name="finger_middle_link_2">
    <!--
			NOTE: This link has an offset in the z-direction based on the models that were
			used to generate grap-it poses.  With the offset below the model appears visually
			correct, but it is suspect.
			-->
    <visual>
      <origin rpy="0 0 0" xyz="0.039 0 0.0075"/>
      <geometry>
        <mesh filename="../meshes/visual/link_2.obj"/>
      </geometry>
      <material name="green"/>
    </visual>
    <collision>
      <origin rpy="0 0 0.0" xyz="0.023 0.002 0.0"/>
      <geometry>
        <box size="0.0285 0.01 0.0308"/>
      </geometry>
      <material name="red">
        <color rgba="1 0 0 1"/>
      </material>
      <surface>
        <friction>
          <ode>
            <mu>1.5</mu>
            <mu2>1.0</mu2>
          </ode>
        </friction>
      </surface>
    </collision>
    <inertial>
      <origin rpy="0 0 0" xyz="0 0 0"/>
      <mass value="0.0601"/>
      <inertia ixx="7.304e-06" ixy="-2.645e-06" ixz="3.537e-07" iyy="1.918e-05" iyz="6.920e-07" izz="2.214e-05"/>
    </inertial>
  </link>
  <link name="finger_middle_link_3">
    <visual>
      <origin rpy="0 0 0.52" xyz="0 0 0"/>
      <geometry>
        <mesh filename="../meshes/visual/link_3.obj"/>
      </geometry>
      <material name="green"/>
    </visual>
    <collision>
      <origin rpy="0 0 0.58" xyz="0.015 0.0135 0.0"/>
      <geometry>
        <box size="0.03 0.007 0.0308"/>
      </geometry>
      <material name="red">
        <color rgba="1 0 0 1"/>
      </material>
      <surface>
        <friction>
          <ode>
            <mu>1.5</mu>
            <mu2>1.0</mu2>
          </ode>
        </friction>
      </surface>
    </collision>
    <inertial>
      <origin rpy="0 0 0" xyz="0 0 0"/>
      <mass value="0.024"/>
      <inertia ixx="2.021e-06" ixy="-7.733e-07" ixz="-1.031e-08" iyy="4.908e-06" iyz="0.0" izz="4.578e-06"/>
    </inertial>
  </link>
  <joint name="finger_middle_joint_1" type="revolute">
    <parent link="finger_middle_link_0"/>
    <child link="finger_middle_link_1"/>
    <axis xyz="0 0 1"/>
    <origin rpy="0 0 0" xyz="0.020 0 0"/>
    <limit effort="100" lower="0" upper="1.2217304764" velocity="100"/>
  </joint>
  <transmission name="finger_middle_transmission_1">
    <type>transmission_interface/SimpleTransmission</type>
    <joint name="finger_middle_joint_1"/>
    <actuator name="finger_middle_actuator_1"/>
  </transmission>
  <joint name="finger_middle_joint_2" type="fixed">
    <parent link="finger_middle_link_1"/>
    <child link="finger_middle_link_2"/>
    <axis xyz="0 0 1"/>
    <origin rpy="0 0 -0.52" xyz="0.050 -.028 0"/>
    <!--<limit effort="100" lower="0" upper="1.57079632679" velocity="100"/>-->
  </joint>
  <!--<transmission name="finger_middle_transmission_2">
    <type>transmission_interface/SimpleTransmission</type>
    <joint name="finger_middle_joint_2"/>
    <actuator name="finger_middle_actuator_2"/>
  </transmission>-->
  <joint name="finger_middle_joint_3" type="revolute">
    <parent link="finger_middle_link_2"/>
    <child link="finger_middle_link_3"/>
    <axis xyz="0 0 1"/>
    <origin rpy="0 0 0" xyz="0.039 0 0"/>
    <!-- upper limit -0.0523598775598 -->
    <limit effort="100" lower="-1.2217304764" upper="1.0" velocity="100"/>
  </joint>
  <transmission name="finger_middle_transmission_3">
    <type>transmission_interface/SimpleTransmission</type>
    <joint name="finger_middle_joint_3"/>
    <actuator name="finger_middle_actuator_3"/>
  </transmission>
  <link name="palm">
    <visual>
      <geometry>
        <mesh filename="../meshes/visual/palm.obj"/>
      </geometry>
      <material name="green">
        <color rgba="0 1 0 1"/>
      </material>
    </visual>
    <collision>
      <origin rpy="0 0 0" xyz="0.0 -0.001 0.0"/>
      <geometry>
        <box size="0.0425 0.1048 0.1302"/>
      </geometry>
      <material name="red">
        <color rgba="1 0 0 1"/>
      </material>
      <surface>
        <friction>
          <ode>
            <mu>1.5</mu>
            <mu2>1.0</mu2>
          </ode>
        </friction>
      </surface>
    </collision>
    <inertial>
      <origin rpy="0 0 0" xyz="0 0 0"/>
      <mass value="1.72568"/>
      <inertia ixx="2.983e-03" ixy="1.075e-04" ixz="4.738e-08" iyy="3.607e-03" iyz="0.0" izz="2.840e-03"/>
    </inertial>
  </link>
  <joint name="palm_finger_1_joint" type="fixed">
    <parent link="palm"/>
    <child link="finger_1_link_0"/>
    <!-- <axis xyz="0 1 0"/> -->
    <!-- Pincher mode: subtract 0.16 to original rpy="0 3.1416 -1.57" -->
    <origin rpy="0 3.0016 -1.57" xyz="-0.0455 0.0214 0.036"/>
    <!-- <limit effort="100" lower="-0.16" upper="0.25" velocity="100"/> -->
  </joint>
  <!--
  <transmission name="palm_finger_1_transmission">
    <type>transmission_interface/SimpleTransmission</type>
    <joint name="palm_finger_1_joint"/>
    <actuator name="palm_finger_1_actuator"/>
  </transmission>
  -->
  <joint name="palm_finger_2_joint" type="fixed">
    <parent link="palm"/>
    <child link="finger_2_link_0"/>
    <!-- <axis xyz="0 1 0"/> -->
    <!-- Pincher mode: add 0.14 to original rpy="0 3.1416 -1.57" -->
    <origin rpy="0 3.2816 -1.57" xyz="-0.0455 0.0214 -0.036"/>
    <!-- <limit effort="100" lower="-0.25" upper="0.16" velocity="100"/> -->
  </joint>
  <!--
  <transmission name="palm_finger_2_transmission">
    <type>transmission_interface/SimpleTransmission</type>
    <joint name="palm_finger_2_joint"/>
    <actuator name="palm_finger_2_actuator"/>
  </transmission>
  -->
  <joint name="palm_finger_middle_joint" type="fixed">
    <parent link="palm"/>
    <child link="finger_middle_link_0"/>
    <axis xyz="0 0 1"/>
    <origin rpy="0 0 1.57" xyz="0.0455 0.0214 0"/>
  </joint>
  <!--
        <include filename="$(find robotiq_3f_gripper_visualization)/cfg/robotiq-3f-gripper_finger_articulated_macro.xacro" />
        <xacro:robotiq-3f-gripper_finger_articulated prefix=""/>
-->
</robot>
