<?xml version="1.0" ?>
<!-- =================================================================================== -->
<!-- |    This document was autogenerated by xacro from robotiq-3f-gripper_articulated.xacro      | -->
<!-- |    EDITING THIS FILE BY HAND IS NOT RECOMMENDED                                 | -->
<!-- =================================================================================== -->
<!-- 
robotiq-3f-gripper_articulated - articulated version of the robotiq robotiq-3f-gripper,
3 fingered gripper.                                                
-->
<robot name="robotiq-3f-gripper_articulated" xmlns:xacro="http://ros.org/wiki/xacro">
  <link name="finger_1_link_0">
    <visual>
      <origin rpy="0 0 0" xyz="0.020 0 0"/>
      <geometry>
        <mesh filename="../meshes/visual/link_0.obj"/>
      </geometry>
      <material name="green">
        <color rgba="0 1 0 1"/>
      </material>
    </visual>
    <!-- <collision>
      <origin rpy="0 3.1416 -1.57" xyz="-0.0455 0.0414 0.036"/>
      <geometry>
        <mesh filename="../meshes/collision/link_0.obj"/>
      </geometry>
      <material name="yellow">
        <color rgba="0 1 1 1"/>
      </material>
    </collision> -->
    <inertial>
      <origin rpy="0 0 0" xyz="0 0 0"/>
      <mass value="0.05"/>
      <inertia ixx="9.98e-9" ixy="4.8e-10" ixz="0.0" iyy="9.64e-9" iyz="0.0" izz="1.282e-8"/>
    </inertial>
  </link>
  <link name="finger_1_link_1">
    <visual>
      <origin rpy="0 0 -0.52" xyz="0.050 -.028 0"/>
      <geometry>
        <mesh filename="../meshes/visual/link_1.obj"/>
      </geometry>
      <material name="green"/>
    </visual>
    <collision>
      <origin rpy="0 0 -0.61" xyz="0.028 -0.016 0.0"/>
      <geometry>
        <box size="0.048 0.018 0.0308"/>
      </geometry>
      <material name="red">
        <color rgba="1 0 0 1"/>
      </material>
    </collision>
    <!-- <collision>
      <origin rpy="0 0 -0.52" xyz="0.050 -.028 0"/>
      <geometry>
        <mesh filename="../meshes/collision/link_1.obj"/>
      </geometry>
      <material name="yellow"/>
    </collision> -->
    <inertial>
      <origin rpy="0 0 0" xyz="0 0 0"/>
      <mass value="0.15"/>
      <inertia ixx= "1.076e-8" ixy= "-3.8e-10" ixz="0.0" iyy= "4.769e-8" iyz="0.0" izz= "5.237e-8"/>
    </inertial>
  </link>
  <link name="finger_1_link_2">
    <!--
			NOTE: This link has an offset in the z-direction based on the models that were
			used to generate grap-it poses.  With the offset below the model appears visually
			correct, but it is suspect.
			-->
    <visual>
      <origin rpy="0 0 0" xyz="0.039 0 0.0075"/>
      <geometry>
        <mesh filename="../meshes/visual/link_2.obj"/>
      </geometry>
      <material name="green"/>
    </visual>
    <collision>
      <origin rpy="0 0 0.0" xyz="0.023 0.002 0.0"/>
      <geometry>
        <box size="0.0285 0.01 0.0308"/>
      </geometry>
      <material name="red">
        <color rgba="1 0 0 1"/>
      </material>
    </collision>
    <!-- <collision>
      <origin rpy="0 0 0" xyz="0.039 0 0.0075"/>
      <geometry>
        <mesh filename="../meshes/collision/link_2.obj"/>
      </geometry>
      <material name="yellow"/>
    </collision> -->
    <inertial>
      <origin rpy="0 0 0" xyz="0 0 0"/>
      <mass value="0.15"/>
      <inertia ixx="4.75e-9" ixy="-1.72e-9" ixz="2.3e-10" iyy="1.247e-8" iyz="4.5e-10" izz="1.44e-8"/>
    </inertial>
  </link>
  <link name="finger_1_link_3">
    <visual>
      <origin rpy="0 0 0.52" xyz="0 0 0"/>
      <geometry>
        <mesh filename="../meshes/visual/link_3.obj"/>
      </geometry>
      <material name="green"/>
    </visual>
    <collision>
      <origin rpy="0 0 0.58" xyz="0.015 0.0135 0.0"/>
      <geometry>
        <box size="0.03 0.007 0.0308"/>
      </geometry>
      <material name="red">
        <color rgba="1 0 0 1"/>
      </material>
    </collision>
    <!-- <collision>
      <origin rpy="0 0 0.52" xyz="0 0 0"/>
      <geometry>
        <mesh filename="../meshes/collision/link_3.obj"/>
      </geometry>
      <material name="yellow"/>
    </collision> -->
    <inertial>
      <origin rpy="0 0 0" xyz="0 0 0"/>
      <mass value="0.05"/>
      <inertia ixx="1.96e-9" ixy="-7.5e-10" ixz="-1e-11" iyy="4.76e-9" iyz="0.0" izz="4.44e-9"/>
    </inertial>
  </link>
  <joint name="finger_1_joint_1" type="revolute">
    <parent link="finger_1_link_0"/>
    <child link="finger_1_link_1"/>
    <axis xyz="0 0 1"/>
    <origin rpy="0 0 0" xyz="0.020 0 0"/>
    <limit effort="100" lower="0" upper="1.2217304764" velocity="100"/>
  </joint>
  <transmission name="finger_1_transmission_1">
    <type>transmission_interface/SimpleTransmission</type>
    <joint name="finger_1_joint_1"/>
    <actuator name="finger_1_actuator_1"/>
  </transmission>
  <joint name="finger_1_joint_2" type="revolute">
    <parent link="finger_1_link_1"/>
    <child link="finger_1_link_2"/>
    <axis xyz="0 0 1"/>
    <origin rpy="0 0 -0.52" xyz="0.050 -.028 0"/>
    <limit effort="100" lower="0" upper="1.57079632679" velocity="100"/>
  </joint>
  <transmission name="finger_1_transmission_2">
    <type>transmission_interface/SimpleTransmission</type>
    <joint name="finger_1_joint_2"/>
    <actuator name="finger_1_actuator_2"/>
  </transmission>
  <joint name="finger_1_joint_3" type="revolute">
    <parent link="finger_1_link_2"/>
    <child link="finger_1_link_3"/>
    <axis xyz="0 0 1"/>
    <origin rpy="0 0 0" xyz="0.039 0 0"/>
    <limit effort="100" lower="-1.2217304764" upper="-0.0523598775598" velocity="100"/>
  </joint>
  <transmission name="finger_1_transmission_3">
    <type>transmission_interface/SimpleTransmission</type>
    <joint name="finger_1_joint_3"/>
    <actuator name="finger_1_actuator_3"/>
  </transmission>
  <link name="finger_2_link_0">
    <visual>
      <origin rpy="0 0 0" xyz="0.020 0 0"/>
      <geometry>
        <mesh filename="../meshes/visual/link_0.obj"/>
      </geometry>
      <material name="green">
        <color rgba="0 1 0 1"/>
      </material>
    </visual>
    <!-- <collision>
      <origin rpy="0 3.1416 -1.57" xyz="-0.0455 0.0414 0.036"/>
      <geometry>
        <mesh filename="../meshes/collision/link_0.obj"/>
      </geometry>
      <material name="yellow">
        <color rgba="0 1 1 1"/>
      </material>
    </collision> -->
    <inertial>
      <origin rpy="0 0 0" xyz="0 0 0"/>
      <mass value="0.05"/>
      <inertia ixx="9.98e-9" ixy="4.8e-10" ixz="0.0" iyy="9.64e-9" iyz="0.0" izz="1.282e-8"/>
    </inertial>
  </link>
  <link name="finger_2_link_1">
    <visual>
      <origin rpy="0 0 -0.52" xyz="0.050 -.028 0"/>
      <geometry>
        <mesh filename="../meshes/visual/link_1.obj"/>
      </geometry>
      <material name="green"/>
    </visual>
    <collision>
      <origin rpy="0 0 -0.61" xyz="0.028 -0.016 0.0"/>
      <geometry>
        <box size="0.048 0.018 0.0308"/>
      </geometry>
      <material name="red">
        <color rgba="1 0 0 1"/>
      </material>
    </collision>
    <!-- <collision>
      <origin rpy="0 0 -0.52" xyz="0.050 -.028 0"/>
      <geometry>
        <mesh filename="../meshes/collision/link_1.obj"/>
      </geometry>
      <material name="yellow"/>
    </collision> -->
    <inertial>
      <origin rpy="0 0 0" xyz="0 0 0"/>
      <mass value="0.15"/>
      <inertia ixx= "1.076e-8" ixy= "-3.8e-10" ixz="0.0" iyy= "4.769e-8" iyz="0.0" izz= "5.237e-8"/>
    </inertial>
  </link>
  <link name="finger_2_link_2">
    <!--
			NOTE: This link has an offset in the z-direction based on the models that were
			used to generate grap-it poses.  With the offset below the model appears visually
			correct, but it is suspect.
			-->
    <visual>
      <origin rpy="0 0 0" xyz="0.039 0 0.0075"/>
      <geometry>
        <mesh filename="../meshes/visual/link_2.obj"/>
      </geometry>
      <material name="green"/>
    </visual>
    <collision>
      <origin rpy="0 0 0.0" xyz="0.023 0.002 0.0"/>
      <geometry>
        <box size="0.0285 0.01 0.0308"/>
      </geometry>
      <material name="red">
        <color rgba="1 0 0 1"/>
      </material>
    </collision>
    <!-- <collision>
      <origin rpy="0 0 0" xyz="0.039 0 0.0075"/>
      <geometry>
        <mesh filename="../meshes/collision/link_2.obj"/>
      </geometry>
      <material name="yellow"/>
    </collision> -->
    <inertial>
      <origin rpy="0 0 0" xyz="0 0 0"/>
      <mass value="0.15"/>
      <inertia ixx="4.75e-9" ixy="-1.72e-9" ixz="2.3e-10" iyy="1.247e-8" iyz="4.5e-10" izz="1.44e-8"/>
    </inertial>
  </link>
  <link name="finger_2_link_3">
    <visual>
      <origin rpy="0 0 0.52" xyz="0 0 0"/>
      <geometry>
        <mesh filename="../meshes/visual/link_3.obj"/>
      </geometry>
      <material name="green"/>
    </visual>
    <collision>
      <origin rpy="0 0 0.58" xyz="0.015 0.0135 0.0"/>
      <geometry>
        <box size="0.03 0.007 0.0308"/>
      </geometry>
      <material name="red">
        <color rgba="1 0 0 1"/>
      </material>
    </collision>
    <!-- <collision>
      <origin rpy="0 0 0.52" xyz="0 0 0"/>
      <geometry>
        <mesh filename="../meshes/collision/link_3.obj"/>
      </geometry>
      <material name="yellow"/>
    </collision> -->
    <inertial>
      <origin rpy="0 0 0" xyz="0 0 0"/>
      <mass value="0.05"/>
      <inertia ixx="1.96e-9" ixy="-7.5e-10" ixz="-1e-11" iyy="4.76e-9" iyz="0.0" izz="4.44e-9"/>
    </inertial>
  </link>
  <joint name="finger_2_joint_1" type="revolute">
    <parent link="finger_2_link_0"/>
    <child link="finger_2_link_1"/>
    <axis xyz="0 0 1"/>
    <origin rpy="0 0 0" xyz="0.020 0 0"/>
    <limit effort="100" lower="0" upper="1.2217304764" velocity="100"/>
  </joint>
  <transmission name="finger_2_transmission_1">
    <type>transmission_interface/SimpleTransmission</type>
    <joint name="finger_2_joint_1"/>
    <actuator name="finger_2_actuator_1"/>
  </transmission>
  <joint name="finger_2_joint_2" type="revolute">
    <parent link="finger_2_link_1"/>
    <child link="finger_2_link_2"/>
    <axis xyz="0 0 1"/>
    <origin rpy="0 0 -0.52" xyz="0.050 -.028 0"/>
    <limit effort="100" lower="0" upper="1.57079632679" velocity="100"/>
  </joint>
  <transmission name="finger_2_transmission_2">
    <type>transmission_interface/SimpleTransmission</type>
    <joint name="finger_2_joint_2"/>
    <actuator name="finger_2_actuator_2"/>
  </transmission>
  <joint name="finger_2_joint_3" type="revolute">
    <parent link="finger_2_link_2"/>
    <child link="finger_2_link_3"/>
    <axis xyz="0 0 1"/>
    <origin rpy="0 0 0" xyz="0.039 0 0"/>
    <limit effort="100" lower="-1.2217304764" upper="-0.0523598775598" velocity="100"/>
  </joint>
  <transmission name="finger_2_transmission_3">
    <type>transmission_interface/SimpleTransmission</type>
    <joint name="finger_2_joint_3"/>
    <actuator name="finger_2_actuator_3"/>
  </transmission>
  <link name="finger_middle_link_0">
    <visual>
      <origin rpy="0 0 0" xyz="0.020 0 0"/>
      <geometry>
        <mesh filename="../meshes/visual/link_0.obj"/>
      </geometry>
      <material name="green">
        <color rgba="0 1 0 1"/>
      </material>
    </visual>
    <!-- <collision>
      <origin rpy="0 3.1416 -1.57" xyz="-0.0455 0.0414 0.036"/>
      <geometry>
        <mesh filename="../meshes/collision/link_0.obj"/>
      </geometry>
      <material name="yellow">
        <color rgba="0 1 1 1"/>
      </material>
    </collision> -->
    <inertial>
      <origin rpy="0 0 0" xyz="0 0 0"/>
      <mass value="0.05"/>
      <inertia ixx="9.98e-9" ixy="4.8e-10" ixz="0.0" iyy="9.64e-9" iyz="0.0" izz="1.282e-8"/>
    </inertial>
  </link>
  <link name="finger_middle_link_1">
    <visual>
      <origin rpy="0 0 -0.52" xyz="0.050 -.028 0"/>
      <geometry>
        <mesh filename="../meshes/visual/link_1.obj"/>
      </geometry>
      <material name="green"/>
    </visual>
    <collision>
      <origin rpy="0 0 -0.61" xyz="0.028 -0.016 0.0"/>
      <geometry>
        <box size="0.048 0.018 0.0308"/>
      </geometry>
      <material name="red">
        <color rgba="1 0 0 1"/>
      </material>
    </collision>
    <!-- <collision>
      <origin rpy="0 0 -0.52" xyz="0.050 -.028 0"/>
      <geometry>
        <mesh filename="../meshes/collision/link_1.obj"/>
      </geometry>
      <material name="yellow"/>
    </collision> -->
    <inertial>
      <origin rpy="0 0 0" xyz="0 0 0"/>
      <mass value="0.15"/>
      <inertia ixx= "1.076e-8" ixy= "-3.8e-10" ixz="0.0" iyy= "4.769e-8" iyz="0.0" izz= "5.237e-8"/>
    </inertial>
  </link>
  <link name="finger_middle_link_2">
    <!--
			NOTE: This link has an offset in the z-direction based on the models that were
			used to generate grap-it poses.  With the offset below the model appears visually
			correct, but it is suspect.
			-->
    <visual>
      <origin rpy="0 0 0" xyz="0.039 0 0.0075"/>
      <geometry>
        <mesh filename="../meshes/visual/link_2.obj"/>
      </geometry>
      <material name="green"/>
    </visual>
    <collision>
      <origin rpy="0 0 0.0" xyz="0.023 0.002 0.0"/>
      <geometry>
        <box size="0.0285 0.01 0.0308"/>
      </geometry>
      <material name="red">
        <color rgba="1 0 0 1"/>
      </material>
    </collision>
    <!-- <collision>
      <origin rpy="0 0 0" xyz="0.039 0 0.0075"/>
      <geometry>
        <mesh filename="../meshes/collision/link_2.obj"/>
      </geometry>
      <material name="yellow"/>
    </collision> -->
    <inertial>
      <origin rpy="0 0 0" xyz="0 0 0"/>
      <mass value="0.15"/>
      <inertia ixx="4.75e-9" ixy="-1.72e-9" ixz="2.3e-10" iyy="1.247e-8" iyz="4.5e-10" izz="1.44e-8"/>
    </inertial>
  </link>
  <link name="finger_middle_link_3">
    <visual>
      <origin rpy="0 0 0.52" xyz="0 0 0"/>
      <geometry>
        <mesh filename="../meshes/visual/link_3.obj"/>
      </geometry>
      <material name="green"/>
    </visual>
    <collision>
      <origin rpy="0 0 0.58" xyz="0.015 0.0135 0.0"/>
      <geometry>
        <box size="0.03 0.007 0.0308"/>
      </geometry>
      <material name="red">
        <color rgba="1 0 0 1"/>
      </material>
    </collision>
    <!-- <collision>
      <origin rpy="0 0 0.52" xyz="0 0 0"/>
      <geometry>
        <mesh filename="../meshes/collision/link_3.obj"/>
      </geometry>
      <material name="yellow"/>
    </collision> -->
    <inertial>
      <origin rpy="0 0 0" xyz="0 0 0"/>
      <mass value="0.05"/>
      <inertia ixx="1.96e-9" ixy="-7.5e-10" ixz="-1e-11" iyy="4.76e-9" iyz="0.0" izz="4.44e-9"/>
    </inertial>
  </link>
  <joint name="finger_middle_joint_1" type="revolute">
    <parent link="finger_middle_link_0"/>
    <child link="finger_middle_link_1"/>
    <axis xyz="0 0 1"/>
    <origin rpy="0 0 0" xyz="0.020 0 0"/>
    <limit effort="100" lower="0" upper="1.2217304764" velocity="100"/>
  </joint>
  <transmission name="finger_middle_transmission_1">
    <type>transmission_interface/SimpleTransmission</type>
    <joint name="finger_middle_joint_1"/>
    <actuator name="finger_middle_actuator_1"/>
  </transmission>
  <joint name="finger_middle_joint_2" type="revolute">
    <parent link="finger_middle_link_1"/>
    <child link="finger_middle_link_2"/>
    <axis xyz="0 0 1"/>
    <origin rpy="0 0 -0.52" xyz="0.050 -.028 0"/>
    <limit effort="100" lower="0" upper="1.57079632679" velocity="100"/>
  </joint>
  <transmission name="finger_middle_transmission_2">
    <type>transmission_interface/SimpleTransmission</type>
    <joint name="finger_middle_joint_2"/>
    <actuator name="finger_middle_actuator_2"/>
  </transmission>
  <joint name="finger_middle_joint_3" type="revolute">
    <parent link="finger_middle_link_2"/>
    <child link="finger_middle_link_3"/>
    <axis xyz="0 0 1"/>
    <origin rpy="0 0 0" xyz="0.039 0 0"/>
    <limit effort="100" lower="-1.2217304764" upper="-0.0523598775598" velocity="100"/>
  </joint>
  <transmission name="finger_middle_transmission_3">
    <type>transmission_interface/SimpleTransmission</type>
    <joint name="finger_middle_joint_3"/>
    <actuator name="finger_middle_actuator_3"/>
  </transmission>
  <link name="palm">
    <visual>
      <geometry>
        <mesh filename="../meshes/visual/palm.obj"/>
      </geometry>
      <material name="green">
        <color rgba="0 1 0 1"/>
      </material>
    </visual>
    <collision>
      <origin rpy="0 0 0" xyz="0.0 -0.001 0.0"/>
      <geometry>
        <box size="0.04 0.1048 0.1302"/>
      </geometry>
      <material name="red">
        <color rgba="1 0 0 1"/>
      </material>
    </collision>
    <!-- <collision>
      <geometry>
        <mesh filename="../meshes/collision/palm.obj"/>
      </geometry>
      <material name="yellow">
        <color rgba="0 1 1 1"/>
      </material>
    </collision> -->
  </link>
  <inertial>
    <origin rpy="0 0 0" xyz="0 0 0"/>
    <mass value="1.3"/>
    <inertia ixx="1.88879e-6" ixy="6.805e-8" ixz="3e-11" iyy="2.28381e-6" iyz="0.0" izz="1.79801e-6"/>
  </inertial>
  <joint name="palm_finger_1_joint" type="revolute">
    <parent link="palm"/>
    <child link="finger_1_link_0"/>
    <axis xyz="0 1 0"/>
    <origin rpy="0 3.1416 -1.57" xyz="-0.0455 0.0214 0.036"/>
    <limit effort="100" lower="-0.16" upper="0.25" velocity="100"/>
  </joint>
  <transmission name="palm_finger_1_transmission">
    <type>transmission_interface/SimpleTransmission</type>
    <joint name="palm_finger_1_joint"/>
    <actuator name="palm_finger_1_actuator"/>
  </transmission>
  <joint name="palm_finger_2_joint" type="revolute">
    <parent link="palm"/>
    <child link="finger_2_link_0"/>
    <axis xyz="0 1 0"/>
    <origin rpy="0 3.1416 -1.57" xyz="-0.0455 0.0214 -0.036"/>
    <limit effort="100" lower="-0.25" upper="0.16" velocity="100"/>
  </joint>
  <transmission name="palm_finger_2_transmission">
    <type>transmission_interface/SimpleTransmission</type>
    <joint name="palm_finger_2_joint"/>
    <actuator name="palm_finger_2_actuator"/>
  </transmission>
  <joint name="palm_finger_middle_joint" type="fixed">
    <parent link="palm"/>
    <child link="finger_middle_link_0"/>
    <axis xyz="0 0 1"/>
    <origin rpy="0 0 1.57" xyz="0.0455 0.0214 0"/>
  </joint>
  <!--
        <include filename="$(find robotiq_3f_gripper_visualization)/cfg/robotiq-3f-gripper_finger_articulated_macro.xacro" />
        <xacro:robotiq-3f-gripper_finger_articulated prefix=""/>
-->
</robot>
