<sdf version='1.6'>
  <model name='robotiq-3f-gripper_articulated'>
    <link name='palm'>
      <pose frame=''>0 0 0 0 -0 0</pose>
      <inertial>
        <pose frame=''>0.0455 0.0214 0 0 -0 0</pose>
        <mass>0.05</mass>
        <inertia>
          <ixx>9.63924e-09</ixx>
          <ixy>-4.79729e-10</ixy>
          <ixz>0</ixz>
          <iyy>9.98076e-09</iyy>
          <iyz>0</iyz>
          <izz>1.282e-08</izz>
        </inertia>
      </inertial>
      <collision name='palm_collision'>
        <pose frame=''>0 -0.001 0 0 -0 0</pose>
        <geometry>
          <box>
            <size>0.04 0.1048 0.1302</size>
          </box>
        </geometry>
      </collision>
      <visual name='palm_visual'>
        <pose frame=''>0 0 0 0 -0 0</pose>
        <geometry>
          <mesh>
            <scale>1 1 1</scale>
            <uri>../meshes/visual/palm.obj</uri>
          </mesh>
        </geometry>
      </visual>
      <visual name='palm_fixed_joint_lump__finger_middle_link_0_visual_1'>
        <pose frame=''>0.045516 0.0414 0 0 -0 1.57</pose>
        <geometry>
          <mesh>
            <scale>1 1 1</scale>
            <uri>../meshes/visual/link_0.obj</uri>
          </mesh>
        </geometry>
      </visual>
    </link>
    <link name='finger_1_link_0'>
      <pose frame=''>-0.0455 0.0214 0.036 3.14159 -7e-06 1.57159</pose>
      <inertial>
        <pose frame=''>0 0 0 0 -0 0</pose>
        <mass>0.05</mass>
        <inertia>
          <ixx>9.98e-09</ixx>
          <ixy>4.8e-10</ixy>
          <ixz>0</ixz>
          <iyy>9.64e-09</iyy>
          <iyz>0</iyz>
          <izz>1.282e-08</izz>
        </inertia>
      </inertial>
      <visual name='finger_1_link_0_visual'>
        <pose frame=''>0.02 0 0 0 -0 0</pose>
        <geometry>
          <mesh>
            <scale>1 1 1</scale>
            <uri>../meshes/visual/link_0.obj</uri>
          </mesh>
        </geometry>
      </visual>
    </link>
    <joint name='palm_finger_1_joint' type='revolute'>
      <child>finger_1_link_0</child>
      <parent>palm</parent>
      <axis>
        <xyz>1 0.000796 0</xyz>
        <limit>
          <lower>-0.16</lower>
          <upper>0.25</upper>
          <effort>100</effort>
          <velocity>100</velocity>
        </limit>
        <dynamics>
          <spring_reference>0</spring_reference>
          <spring_stiffness>0</spring_stiffness>
        </dynamics>
        <use_parent_model_frame>1</use_parent_model_frame>
      </axis>
    </joint>
    <link name='finger_1_link_1'>
      <pose frame=''>-0.045516 0.0414 0.036 3.14159 -7e-06 1.57159</pose>
      <inertial>
        <pose frame=''>0 0 0 0 -0 0</pose>
        <mass>0.15</mass>
        <inertia>
          <ixx>1.076e-08</ixx>
          <ixy>-3.8e-10</ixy>
          <ixz>0</ixz>
          <iyy>4.769e-08</iyy>
          <iyz>0</iyz>
          <izz>5.237e-08</izz>
        </inertia>
      </inertial>
      <collision name='finger_1_link_1_collision'>
        <pose frame=''>0.028 -0.016 0 0 0 -0.61</pose>
        <geometry>
          <box>
            <size>0.048 0.018 0.0308</size>
          </box>
        </geometry>
      </collision>
      <visual name='finger_1_link_1_visual'>
        <pose frame=''>0.05 -0.028 0 0 0 -0.52</pose>
        <geometry>
          <mesh>
            <scale>1 1 1</scale>
            <uri>../meshes/visual/link_1.obj</uri>
          </mesh>
        </geometry>
      </visual>
    </link>
    <joint name='finger_1_joint_1' type='revolute'>
      <child>finger_1_link_1</child>
      <parent>finger_1_link_0</parent>
      <axis>
        <xyz>-0 7e-06 -1</xyz>
        <limit>
          <lower>0</lower>
          <upper>1.22173</upper>
          <effort>100</effort>
          <velocity>100</velocity>
        </limit>
        <dynamics>
          <spring_reference>0</spring_reference>
          <spring_stiffness>0</spring_stiffness>
        </dynamics>
        <use_parent_model_frame>1</use_parent_model_frame>
      </axis>
    </joint>
    <link name='finger_1_link_2'>
      <pose frame=''>-0.073556 0.091378 0.036001 3.14159 -6e-06 2.09159</pose>
      <inertial>
        <pose frame=''>0 0 0 0 -0 0</pose>
        <mass>0.15</mass>
        <inertia>
          <ixx>4.75e-09</ixx>
          <ixy>-1.72e-09</ixy>
          <ixz>2.3e-10</ixz>
          <iyy>1.247e-08</iyy>
          <iyz>4.5e-10</iyz>
          <izz>1.44e-08</izz>
        </inertia>
      </inertial>
      <collision name='finger_1_link_2_collision'>
        <pose frame=''>0.023 0.002 0 0 -0 0</pose>
        <geometry>
          <box>
            <size>0.0285 0.01 0.0308</size>
          </box>
        </geometry>
      </collision>
      <visual name='finger_1_link_2_visual'>
        <pose frame=''>0.039 0 0.0075 0 -0 0</pose>
        <geometry>
          <mesh>
            <scale>1 1 1</scale>
            <uri>../meshes/visual/link_2.obj</uri>
          </mesh>
        </geometry>
      </visual>
    </link>
    <joint name='finger_1_joint_2' type='revolute'>
      <child>finger_1_link_2</child>
      <parent>finger_1_link_1</parent>
      <axis>
        <xyz>-0 7e-06 -1</xyz>
        <limit>
          <lower>0</lower>
          <upper>1.5708</upper>
          <effort>100</effort>
          <velocity>100</velocity>
        </limit>
        <dynamics>
          <spring_reference>0</spring_reference>
          <spring_stiffness>0</spring_stiffness>
        </dynamics>
        <use_parent_model_frame>1</use_parent_model_frame>
      </axis>
    </joint>
    <link name='finger_1_link_3'>
      <pose frame=''>-0.092961 0.125207 0.036001 3.14159 -6e-06 2.09159</pose>
      <inertial>
        <pose frame=''>0 0 0 0 -0 0</pose>
        <mass>0.05</mass>
        <inertia>
          <ixx>1.96e-09</ixx>
          <ixy>-7.5e-10</ixy>
          <ixz>-1e-11</ixz>
          <iyy>4.76e-09</iyy>
          <iyz>0</iyz>
          <izz>4.44e-09</izz>
        </inertia>
      </inertial>
      <collision name='finger_1_link_3_collision'>
        <pose frame=''>0.015 0.0135 0 0 -0 0.58</pose>
        <geometry>
          <box>
            <size>0.03 0.007 0.0308</size>
          </box>
        </geometry>
      </collision>
      <visual name='finger_1_link_3_visual'>
        <pose frame=''>0 0 0 0 -0 0.52</pose>
        <geometry>
          <mesh>
            <scale>1 1 1</scale>
            <uri>../meshes/visual/link_3.obj</uri>
          </mesh>
        </geometry>
      </visual>
    </link>
    <joint name='finger_1_joint_3' type='revolute'>
      <child>finger_1_link_3</child>
      <parent>finger_1_link_2</parent>
      <axis>
        <xyz>-0 7e-06 -1</xyz>
        <limit>
          <lower>-1.22173</lower>
          <upper>-0.0523599</upper>
          <effort>100</effort>
          <velocity>100</velocity>
        </limit>
        <dynamics>
          <spring_reference>0</spring_reference>
          <spring_stiffness>0</spring_stiffness>
        </dynamics>
        <use_parent_model_frame>1</use_parent_model_frame>
      </axis>
    </joint>
    <link name='finger_2_link_0'>
      <pose frame=''>-0.0455 0.0214 -0.036 3.14159 -7e-06 1.57159</pose>
      <inertial>
        <pose frame=''>0 0 0 0 -0 0</pose>
        <mass>0.05</mass>
        <inertia>
          <ixx>9.98e-09</ixx>
          <ixy>4.8e-10</ixy>
          <ixz>0</ixz>
          <iyy>9.64e-09</iyy>
          <iyz>0</iyz>
          <izz>1.282e-08</izz>
        </inertia>
      </inertial>
      <visual name='finger_2_link_0_visual'>
        <pose frame=''>0.02 0 0 0 -0 0</pose>
        <geometry>
          <mesh>
            <scale>1 1 1</scale>
            <uri>../meshes/visual/link_0.obj</uri>
          </mesh>
        </geometry>
      </visual>
    </link>
    <joint name='palm_finger_2_joint' type='revolute'>
      <child>finger_2_link_0</child>
      <parent>palm</parent>
      <axis>
        <xyz>1 0.000796 0</xyz>
        <limit>
          <lower>-0.25</lower>
          <upper>0.16</upper>
          <effort>100</effort>
          <velocity>100</velocity>
        </limit>
        <dynamics>
          <spring_reference>0</spring_reference>
          <spring_stiffness>0</spring_stiffness>
        </dynamics>
        <use_parent_model_frame>1</use_parent_model_frame>
      </axis>
    </joint>
    <link name='finger_2_link_1'>
      <pose frame=''>-0.045516 0.0414 -0.036 3.14159 -7e-06 1.57159</pose>
      <inertial>
        <pose frame=''>0 0 0 0 -0 0</pose>
        <mass>0.15</mass>
        <inertia>
          <ixx>1.076e-08</ixx>
          <ixy>-3.8e-10</ixy>
          <ixz>0</ixz>
          <iyy>4.769e-08</iyy>
          <iyz>0</iyz>
          <izz>5.237e-08</izz>
        </inertia>
      </inertial>
      <collision name='finger_2_link_1_collision'>
        <pose frame=''>0.028 -0.016 0 0 0 -0.61</pose>
        <geometry>
          <box>
            <size>0.048 0.018 0.0308</size>
          </box>
        </geometry>
      </collision>
      <visual name='finger_2_link_1_visual'>
        <pose frame=''>0.05 -0.028 0 0 0 -0.52</pose>
        <geometry>
          <mesh>
            <scale>1 1 1</scale>
            <uri>../meshes/visual/link_1.obj</uri>
          </mesh>
        </geometry>
      </visual>
    </link>
    <joint name='finger_2_joint_1' type='revolute'>
      <child>finger_2_link_1</child>
      <parent>finger_2_link_0</parent>
      <axis>
        <xyz>-0 7e-06 -1</xyz>
        <limit>
          <lower>0</lower>
          <upper>1.22173</upper>
          <effort>100</effort>
          <velocity>100</velocity>
        </limit>
        <dynamics>
          <spring_reference>0</spring_reference>
          <spring_stiffness>0</spring_stiffness>
        </dynamics>
        <use_parent_model_frame>1</use_parent_model_frame>
      </axis>
    </joint>
    <link name='finger_2_link_2'>
      <pose frame=''>-0.073556 0.091378 -0.036 3.14159 -6e-06 2.09159</pose>
      <inertial>
        <pose frame=''>0 0 0 0 -0 0</pose>
        <mass>0.15</mass>
        <inertia>
          <ixx>4.75e-09</ixx>
          <ixy>-1.72e-09</ixy>
          <ixz>2.3e-10</ixz>
          <iyy>1.247e-08</iyy>
          <iyz>4.5e-10</iyz>
          <izz>1.44e-08</izz>
        </inertia>
      </inertial>
      <collision name='finger_2_link_2_collision'>
        <pose frame=''>0.023 0.002 0 0 -0 0</pose>
        <geometry>
          <box>
            <size>0.0285 0.01 0.0308</size>
          </box>
        </geometry>
      </collision>
      <visual name='finger_2_link_2_visual'>
        <pose frame=''>0.039 0 0.0075 0 -0 0</pose>
        <geometry>
          <mesh>
            <scale>1 1 1</scale>
            <uri>../meshes/visual/link_2.obj</uri>
          </mesh>
        </geometry>
      </visual>
    </link>
    <joint name='finger_2_joint_2' type='revolute'>
      <child>finger_2_link_2</child>
      <parent>finger_2_link_1</parent>
      <axis>
        <xyz>-0 7e-06 -1</xyz>
        <limit>
          <lower>0</lower>
          <upper>1.5708</upper>
          <effort>100</effort>
          <velocity>100</velocity>
        </limit>
        <dynamics>
          <spring_reference>0</spring_reference>
          <spring_stiffness>0</spring_stiffness>
        </dynamics>
        <use_parent_model_frame>1</use_parent_model_frame>
      </axis>
    </joint>
    <link name='finger_2_link_3'>
      <pose frame=''>-0.092961 0.125207 -0.035999 3.14159 -6e-06 2.09159</pose>
      <inertial>
        <pose frame=''>0 0 0 0 -0 0</pose>
        <mass>0.05</mass>
        <inertia>
          <ixx>1.96e-09</ixx>
          <ixy>-7.5e-10</ixy>
          <ixz>-1e-11</ixz>
          <iyy>4.76e-09</iyy>
          <iyz>0</iyz>
          <izz>4.44e-09</izz>
        </inertia>
      </inertial>
      <collision name='finger_2_link_3_collision'>
        <pose frame=''>0.015 0.0135 0 0 -0 0.58</pose>
        <geometry>
          <box>
            <size>0.03 0.007 0.0308</size>
          </box>
        </geometry>
      </collision>
      <visual name='finger_2_link_3_visual'>
        <pose frame=''>0 0 0 0 -0 0.52</pose>
        <geometry>
          <mesh>
            <scale>1 1 1</scale>
            <uri>../meshes/visual/link_3.obj</uri>
          </mesh>
        </geometry>
      </visual>
    </link>
    <joint name='finger_2_joint_3' type='revolute'>
      <child>finger_2_link_3</child>
      <parent>finger_2_link_2</parent>
      <axis>
        <xyz>-0 7e-06 -1</xyz>
        <limit>
          <lower>-1.22173</lower>
          <upper>-0.0523599</upper>
          <effort>100</effort>
          <velocity>100</velocity>
        </limit>
        <dynamics>
          <spring_reference>0</spring_reference>
          <spring_stiffness>0</spring_stiffness>
        </dynamics>
        <use_parent_model_frame>1</use_parent_model_frame>
      </axis>
    </joint>
    <link name='finger_middle_link_1'>
      <pose frame=''>0.045516 0.0414 0 0 -0 1.57</pose>
      <inertial>
        <pose frame=''>0 0 0 0 -0 0</pose>
        <mass>0.15</mass>
        <inertia>
          <ixx>1.076e-08</ixx>
          <ixy>-3.8e-10</ixy>
          <ixz>0</ixz>
          <iyy>4.769e-08</iyy>
          <iyz>0</iyz>
          <izz>5.237e-08</izz>
        </inertia>
      </inertial>
      <collision name='finger_middle_link_1_collision'>
        <pose frame=''>0.028 -0.016 0 0 0 -0.61</pose>
        <geometry>
          <box>
            <size>0.048 0.018 0.0308</size>
          </box>
        </geometry>
      </collision>
      <visual name='finger_middle_link_1_visual'>
        <pose frame=''>0.05 -0.028 0 0 0 -0.52</pose>
        <geometry>
          <mesh>
            <scale>1 1 1</scale>
            <uri>../meshes/visual/link_1.obj</uri>
          </mesh>
        </geometry>
      </visual>
    </link>
    <joint name='finger_middle_joint_1' type='revolute'>
      <child>finger_middle_link_1</child>
      <parent>palm</parent>
      <axis>
        <xyz>0 0 1</xyz>
        <limit>
          <lower>0</lower>
          <upper>1.22173</upper>
          <effort>100</effort>
          <velocity>100</velocity>
        </limit>
        <dynamics>
          <spring_reference>0</spring_reference>
          <spring_stiffness>0</spring_stiffness>
        </dynamics>
        <use_parent_model_frame>1</use_parent_model_frame>
      </axis>
    </joint>
    <link name='finger_middle_link_2'>
      <pose frame=''>0.073556 0.091378 0 0 -0 1.05</pose>
      <inertial>
        <pose frame=''>0 0 0 0 -0 0</pose>
        <mass>0.15</mass>
        <inertia>
          <ixx>4.75e-09</ixx>
          <ixy>-1.72e-09</ixy>
          <ixz>2.3e-10</ixz>
          <iyy>1.247e-08</iyy>
          <iyz>4.5e-10</iyz>
          <izz>1.44e-08</izz>
        </inertia>
      </inertial>
      <collision name='finger_middle_link_2_collision'>
        <pose frame=''>0.023 0.002 0 0 -0 0</pose>
        <geometry>
          <box>
            <size>0.0285 0.01 0.0308</size>
          </box>
        </geometry>
      </collision>
      <visual name='finger_middle_link_2_visual'>
        <pose frame=''>0.039 0 0.0075 0 -0 0</pose>
        <geometry>
          <mesh>
            <scale>1 1 1</scale>
            <uri>../meshes/visual/link_2.obj</uri>
          </mesh>
        </geometry>
      </visual>
    </link>
    <joint name='finger_middle_joint_2' type='revolute'>
      <child>finger_middle_link_2</child>
      <parent>finger_middle_link_1</parent>
      <axis>
        <xyz>0 0 1</xyz>
        <limit>
          <lower>0</lower>
          <upper>1.5708</upper>
          <effort>100</effort>
          <velocity>100</velocity>
        </limit>
        <dynamics>
          <spring_reference>0</spring_reference>
          <spring_stiffness>0</spring_stiffness>
        </dynamics>
        <use_parent_model_frame>1</use_parent_model_frame>
      </axis>
    </joint>
    <link name='finger_middle_link_3'>
      <pose frame=''>0.092961 0.125207 0 0 -0 1.05</pose>
      <inertial>
        <pose frame=''>0 0 0 0 -0 0</pose>
        <mass>0.05</mass>
        <inertia>
          <ixx>1.96e-09</ixx>
          <ixy>-7.5e-10</ixy>
          <ixz>-1e-11</ixz>
          <iyy>4.76e-09</iyy>
          <iyz>0</iyz>
          <izz>4.44e-09</izz>
        </inertia>
      </inertial>
      <collision name='finger_middle_link_3_collision'>
        <pose frame=''>0.015 0.0135 0 0 -0 0.58</pose>
        <geometry>
          <box>
            <size>0.03 0.007 0.0308</size>
          </box>
        </geometry>
      </collision>
      <visual name='finger_middle_link_3_visual'>
        <pose frame=''>0 0 0 0 -0 0.52</pose>
        <geometry>
          <mesh>
            <scale>1 1 1</scale>
            <uri>../meshes/visual/link_3.obj</uri>
          </mesh>
        </geometry>
      </visual>
    </link>
    <joint name='finger_middle_joint_3' type='revolute'>
      <child>finger_middle_link_3</child>
      <parent>finger_middle_link_2</parent>
      <axis>
        <xyz>0 0 1</xyz>
        <limit>
          <lower>-1.22173</lower>
          <upper>-0.0523599</upper>
          <effort>100</effort>
          <velocity>100</velocity>
        </limit>
        <dynamics>
          <spring_reference>0</spring_reference>
          <spring_stiffness>0</spring_stiffness>
        </dynamics>
        <use_parent_model_frame>1</use_parent_model_frame>
      </axis>
    </joint>
  </model>
</sdf>
